ERROR:websockets.server:connection handler failed
Traceback (most recent call last):
  File "C:\Users\jmorr\AppData\Local\Programs\Python\Python310\lib\asyncio\windows_events.py", line 485, in finish_recv
    return ov.getresult()
OSError: [WinError 64] The specified network name is no longer available

During handling of the above exception, another exception occurred:

Traceback (most recent call last):
  File "C:\Users\jmorr\AppData\Local\Programs\Python\Python310\lib\site-packages\websockets\legacy\protocol.py", line 968, in transfer_data
    message = await self.read_message()
  File "C:\Users\jmorr\AppData\Local\Programs\Python\Python310\lib\site-packages\websockets\legacy\protocol.py", line 1038, in read_message
    frame = await self.read_data_frame(max_size=self.max_size)
  File "C:\Users\jmorr\AppData\Local\Programs\Python\Python310\lib\site-packages\websockets\legacy\protocol.py", line 1113, in read_data_frame
    frame = await self.read_frame(max_size)
  File "C:\Users\jmorr\AppData\Local\Programs\Python\Python310\lib\site-packages\websockets\legacy\protocol.py", line 1170, in read_frame
    frame = await Frame.read(
  File "C:\Users\jmorr\AppData\Local\Programs\Python\Python310\lib\site-packages\websockets\legacy\framing.py", line 69, in read
    data = await reader(2)
  File "C:\Users\jmorr\AppData\Local\Programs\Python\Python310\lib\asyncio\streams.py", line 707, in readexactly
    await self._wait_for_data('readexactly')
  File "C:\Users\jmorr\AppData\Local\Programs\Python\Python310\lib\asyncio\streams.py", line 501, in _wait_for_data
    await self._waiter
  File "C:\Users\jmorr\AppData\Local\Programs\Python\Python310\lib\asyncio\proactor_events.py", line 282, in _loop_reading
    length = fut.result()
  File "C:\Users\jmorr\AppData\Local\Programs\Python\Python310\lib\asyncio\windows_events.py", line 817, in _poll
    value = callback(transferred, key, ov)
  File "C:\Users\jmorr\AppData\Local\Programs\Python\Python310\lib\asyncio\windows_events.py", line 489, in finish_recv
    raise ConnectionResetError(*exc.args)
ConnectionResetError: [WinError 64] The specified network name is no longer available

The above exception was the direct cause of the following exception:

Traceback (most recent call last):
  File "C:\Users\jmorr\AppData\Local\Programs\Python\Python310\lib\site-packages\websockets\legacy\server.py", line 236, in handler
    await self.ws_handler(self)
  File "C:\Users\jmorr\AppData\Local\Programs\Python\Python310\lib\site-packages\websockets\legacy\server.py", line 1175, in _ws_handler
    return await cast(
  File "C:\Users\jmorr\PycharmProjects\Websockets\python_ota_server.py", line 221, in ws_server
    async for message in websocket:
  File "C:\Users\jmorr\AppData\Local\Programs\Python\Python310\lib\site-packages\websockets\legacy\protocol.py", line 497, in __aiter__
    yield await self.recv()
  File "C:\Users\jmorr\AppData\Local\Programs\Python\Python310\lib\site-packages\websockets\legacy\protocol.py", line 568, in recv
    await self.ensure_open()
  File "C:\Users\jmorr\AppData\Local\Programs\Python\Python310\lib\site-packages\websockets\legacy\protocol.py", line 944, in ensure_open
    raise self.connection_closed_exc()
websockets.exceptions.ConnectionClosedError: no close frame received or sent
